#VRML_SIM R2019a utf8
WorldInfo {
}
Viewpoint {
  orientation -0.6453753947321893 0.697353125482533 0.3117518536496833 1.2116168305051833
  position 0.8353433112406244 1.9056673152699442 0.5942498620701517
}
TexturedBackground {
}
TexturedBackgroundLight {
}
Floor {
}
Solid {
  translation 0 0.8 0
  children [
    Group {
      children [
        Shape {
          appearance DEF RED PBRAppearance {
            baseColor 0.8 0 0
            roughness 1
            metalness 0
          }
          geometry Box {
            size 0.4 0.05 0.4
          }
        }
        Transform {
          translation 0.15 -0.42 0.15
          rotation -0.7071067811865475 0 0.7071067811865475 0.1308996938995747
          children [
            Shape {
              appearance USE RED
              geometry DEF CY_B Cylinder {
                height 0.8
                radius 0.02
              }
            }
          ]
        }
        Transform {
          translation 0.15 -0.42 -0.15
          rotation -0.7071067811865475 0 -0.7071067811865475 -0.1308996938995747
          children [
            Shape {
              appearance USE RED
              geometry USE CY_B
            }
          ]
        }
        Transform {
          translation -0.15 -0.42 -0.15
          rotation 0.7071067811865475 0 -0.7071067811865475 0.1308996938995747
          children [
            Shape {
              appearance USE RED
              geometry USE CY_B
            }
          ]
        }
        Transform {
          translation -0.15 -0.42 0.15
          rotation 0.7071067811865475 0 0.7071067811865475 -0.1308996938995747
          children [
            Shape {
              appearance USE RED
              geometry USE CY_B
            }
          ]
        }
        DEF CY_MEDIA Transform {
          translation 0 -0.4 0.15
          rotation 0 0 1 1.5707996938995747
          children [
            Shape {
              appearance USE RED
              geometry DEF CY_M Cylinder {
                height 0.30000000000000004
                radius 0.01
              }
            }
          ]
        }
        Transform {
          translation 0 -0.4 -0.15
          rotation 0 0 1 1.5707996938995747
          children [
            Shape {
              appearance USE RED
              geometry USE CY_M
            }
          ]
        }
        Transform {
          translation 0.15 -0.4 0
          rotation 1 0 0 1.5707996938995747
          children [
            Shape {
              appearance USE RED
              geometry USE CY_M
            }
          ]
        }
        Transform {
          translation -0.15 -0.4 0
          rotation 1 0 0 1.5707996938995747
          children [
            Shape {
              appearance USE RED
              geometry USE CY_M
            }
          ]
        }
      ]
    }
    Group {
      children [
        DEF C_G Transform {
          translation 0 0.125 0
          children [
            Shape {
              appearance DEF GREEN PBRAppearance {
                baseColor 0.45098039215686275 0.8235294117647058 0.08627450980392157
                roughness 1
                metalness 0
              }
              geometry Cylinder {
                height 0.2
                radius 0.04
              }
            }
          ]
        }
        Transform {
          translation 0 0.25 0
          rotation 0 0 1 1.5707996938995747
          children [
            Shape {
              appearance USE GREEN
              geometry Cylinder {
                height 0.2
                radius 0.05
              }
            }
          ]
        }
        HingeJoint {
          jointParameters HingeJointParameters {
            axis 0 1 0
            anchor -0.1 0.25 0
          }
          endPoint Solid {
            translation -0.2 0.25 0
            rotation 0 0 1 1.5707996938995745
            children [
              Shape {
                appearance USE GREEN
                geometry Cylinder {
                  height 0.2
                  radius 0.02
                }
              }
              Transform {
                translation 0 0.14 0
                children [
                  Shape {
                    appearance USE GREEN
                    geometry Box {
                      size 0.08 0.08 0.01
                    }
                  }
                ]
              }
            ]
            physics Physics {
            }
          }
        }
        HingeJoint {
          jointParameters HingeJointParameters {
            anchor 0.11 0.25 0
          }
          endPoint Solid {
            translation 0.11 0.25 0
            rotation 0 0 1 1.5707996938995745
            children [
              Shape {
                appearance USE GREEN
                geometry Cylinder {
                  height 0.02
                  radius 0.03
                }
              }
              Transform {
                translation 0.07 0 0
                rotation 0 0 1 1.5707996938995747
                children [
                  DEF ASPA Shape {
                    appearance USE GREEN
                    geometry Cylinder {
                      height 0.1
                      radius 0.01
                    }
                  }
                ]
              }
              Transform {
                translation -0.07 0 0
                rotation 0 0 1 1.5707996938995747
                children [
                  USE ASPA
                ]
              }
              Transform {
                translation 0 0 0.07
                rotation 1 0 0 1.5708003061004252
                children [
                  USE ASPA
                ]
              }
              Transform {
                translation 0 0 -0.07
                rotation 1 0 0 1.5708003061004252
                children [
                  USE ASPA
                ]
              }
              Transform {
                translation 0.05 0 -0.05
                rotation 0.7071067811865475 0 0.7071067811865475 1.5707996938995747
                children [
                  USE ASPA
                ]
              }
              Transform {
                translation -0.05 0 0.05
                rotation 0.7071067811865475 0 0.7071067811865475 1.5708003061004252
                children [
                  USE ASPA
                ]
              }
              Transform {
                translation 0.05 0 0.05
                rotation -0.7071067811865475 0 0.7071067811865475 1.5707996938995747
                children [
                  USE ASPA
                ]
              }
              DEF CY Transform {
                translation -0.05 0 -0.05
                rotation -0.7071067811865475 0 0.7071067811865475 1.5707996938995747
                children [
                  USE ASPA
                ]
              }
              Transform {
                translation 0.14 0 0
                children [
                  DEF A Shape {
                    appearance USE GREEN
                    geometry Box {
                      size 0.04 0.01 0.04
                    }
                  }
                ]
              }
              Transform {
                translation -0.14 0 0
                children [
                  USE A
                ]
              }
              Transform {
                translation 0 0 0.14
                children [
                  USE A
                ]
              }
              Transform {
                translation 0 0 -0.14
                children [
                  USE A
                ]
              }
              Transform {
                translation 0.1 0 0.1
                rotation 0 1 0 0.6545
                children [
                  USE A
                ]
              }
              Transform {
                translation -0.1 0 0.1
                rotation 0 1 0 0.6544996938995746
                children [
                  USE A
                ]
              }
              Transform {
                translation 0.1 0 -0.1
                rotation 0 1 0 0.6544996938995746
                children [
                  USE A
                ]
              }
              Transform {
                translation -0.1 0 -0.1
                rotation 0 1 0 0.6544996938995746
                children [
                  USE A
                ]
              }
            ]
            name "solid(1)"
            physics Physics {
            }
          }
        }
      ]
    }
  ]
}
